Traceback (most recent call last):
  File "/home/ilias/.local/lib/python3.8/site-packages/lockfile/pidlockfile.py", line 77, in acquire
    write_pid_to_pidfile(self.path)
  File "/home/ilias/.local/lib/python3.8/site-packages/lockfile/pidlockfile.py", line 161, in write_pid_to_pidfile
    pidfile_fd = os.open(pidfile_path, open_flags, open_mode)
FileExistsError: [Errno 17] File exists: '/home/ilias/airflow/airflow-webserver-monitor.pid'

During handling of the above exception, another exception occurred:

Traceback (most recent call last):
  File "/home/ilias/.local/bin/airflow", line 8, in <module>
    sys.exit(main())
  File "/home/ilias/.local/lib/python3.8/site-packages/airflow/__main__.py", line 48, in main
    args.func(args)
  File "/home/ilias/.local/lib/python3.8/site-packages/airflow/cli/cli_parser.py", line 48, in command
    return func(*args, **kwargs)
  File "/home/ilias/.local/lib/python3.8/site-packages/airflow/utils/cli.py", line 92, in wrapper
    return f(*args, **kwargs)
  File "/home/ilias/.local/lib/python3.8/site-packages/airflow/cli/commands/webserver_command.py", line 469, in webserver
    with ctx:
  File "/home/ilias/.local/lib/python3.8/site-packages/daemon/daemon.py", line 389, in __enter__
    self.open()
  File "/home/ilias/.local/lib/python3.8/site-packages/daemon/daemon.py", line 381, in open
    self.pidfile.__enter__()
  File "/home/ilias/.local/lib/python3.8/site-packages/lockfile/__init__.py", line 197, in __enter__
    self.acquire()
  File "/home/ilias/.local/lib/python3.8/site-packages/daemon/pidfile.py", line 57, in acquire
    super().acquire(timeout, *args, **kwargs)
  File "/home/ilias/.local/lib/python3.8/site-packages/lockfile/pidlockfile.py", line 87, in acquire
    raise AlreadyLocked("%s is already locked" %
lockfile.AlreadyLocked: /home/ilias/airflow/airflow-webserver-monitor.pid is already locked
